<?xml version="1.0" ?>
<robot name="vx300s" version="1.0">
  <material name="interbotix_black">
    <texture filename="/home/r2ci/eagerx-dev/eagerx_interbotix/eagerx_interbotix/xseries/assets/meshes/interbotix_black.png"/>
  </material>
  <link name="world"/>
  <joint name="fixed" type="fixed">
    <parent link="world"/>
    <child link="vx300s/base_link"/>
  </joint>
  <link name="vx300s/base_link">
    <inertial>
      <origin xyz="-0.0534774 -0.000562575 0.0205961" rpy="0.0 0.0 1.5707963267948966"/>
      <mass value="0.969034"/>
      <inertia ixx="0.006024" ixy="4.713e-05" ixz="3.851e-06" iyy="0.0017" iyz="-8.415e-05" izz="0.007162"/>
    </inertial>
    <visual>
      <origin xyz="0.0 0.0 0.0" rpy="0.0 0.0 1.5707963267948966"/>
      <geometry>
        <mesh filename="/home/r2ci/eagerx-dev/eagerx_interbotix/eagerx_interbotix/xseries/assets/meshes/vx300s_meshes/vx300s_1_base.stl" scale="0.001 0.001 0.001"/>
      </geometry>
      <material name="interbotix_black"/>
    </visual>
    <collision>
      <origin xyz="0.0 0.0 0.0" rpy="0.0 0.0 1.5707963267948966"/>
      <geometry>
        <mesh filename="/home/r2ci/eagerx-dev/eagerx_interbotix/eagerx_interbotix/xseries/assets/meshes/vx300s_meshes/vx300s_1_base.stl" scale="0.001 0.001 0.001"/>
      </geometry>
    </collision>
  </link>
  <joint name="waist" type="revolute">
    <origin xyz="0.0 0.0 0.079" rpy="0.0 0.0 0.0"/>
    <axis xyz="0.0 0.0 1.0"/>
    <parent link="vx300s/base_link"/>
    <child link="vx300s/shoulder_link"/>
    <limit effort="10.0" lower="-3.141582653589793" upper="3.141582653589793" velocity="3.141592653589793"/>
    <dynamics friction="0.1"/>
  </joint>
  <transmission name="trans_waist">
    <type>transmission_interface/SimpleTransmission</type>
    <joint name="waist">
      <hardwareInterface>hardware_interface/EffortJointInterface</hardwareInterface>
    </joint>
    <actuator name="waist_motor">
      <mechanicalReduction>1.0</mechanicalReduction>
    </actuator>
  </transmission>
  <link name="vx300s/shoulder_link">
    <inertial>
      <origin xyz="0.000259233 -3.3552e-06 0.0116129" rpy="0.0 0.0 1.5707963267948966"/>
      <mass value="0.798614"/>
      <inertia ixx="0.0009388" ixy="-1e-09" ixz="-1.91e-08" iyy="0.001138" iyz="5.9568e-06" izz="0.001201"/>
    </inertial>
    <visual>
      <origin xyz="0.0 0.0 -0.003" rpy="0.0 0.0 1.5707963267948966"/>
      <geometry>
        <mesh filename="/home/r2ci/eagerx-dev/eagerx_interbotix/eagerx_interbotix/xseries/assets/meshes/vx300s_meshes/vx300s_2_shoulder.stl" scale="0.001 0.001 0.001"/>
      </geometry>
      <material name="interbotix_black"/>
    </visual>
    <collision>
      <origin xyz="0.0 0.0 -0.003" rpy="0.0 0.0 1.5707963267948966"/>
      <geometry>
        <mesh filename="/home/r2ci/eagerx-dev/eagerx_interbotix/eagerx_interbotix/xseries/assets/meshes/vx300s_meshes/vx300s_2_shoulder.stl" scale="0.001 0.001 0.001"/>
      </geometry>
    </collision>
  </link>
  <joint name="shoulder" type="revolute">
    <origin xyz="0.0 0.0 0.04805" rpy="0.0 0.0 0.0"/>
    <axis xyz="0.0 1.0 0.0"/>
    <parent link="vx300s/shoulder_link"/>
    <child link="vx300s/upper_arm_link"/>
    <limit effort="20.0" lower="-1.8500490071139892" upper="1.2566370614359172" velocity="3.141592653589793"/>
    <dynamics friction="0.1"/>
  </joint>
  <transmission name="trans_shoulder">
    <type>transmission_interface/SimpleTransmission</type>
    <joint name="shoulder">
      <hardwareInterface>hardware_interface/EffortJointInterface</hardwareInterface>
    </joint>
    <actuator name="shoulder_motor">
      <mechanicalReduction>1.0</mechanicalReduction>
    </actuator>
  </transmission>
  <link name="vx300s/upper_arm_link">
    <inertial>
      <origin xyz="0.0206949 4e-10 0.226459" rpy="0.0 0.0 1.5707963267948966"/>
      <mass value="0.792592"/>
      <inertia ixx="0.008925" ixy="0.0" ixz="0.0" iyy="0.008937" iyz="0.001201" izz="0.0009357"/>
    </inertial>
    <visual>
      <origin xyz="0.0 0.0 0.0" rpy="0.0 0.0 1.5707963267948966"/>
      <geometry>
        <mesh filename="/home/r2ci/eagerx-dev/eagerx_interbotix/eagerx_interbotix/xseries/assets/meshes/vx300s_meshes/vx300s_3_upper_arm.stl" scale="0.001 0.001 0.001"/>
      </geometry>
      <material name="interbotix_black"/>
    </visual>
    <collision>
      <origin xyz="0.0 0.0 0.0" rpy="0.0 0.0 1.5707963267948966"/>
      <geometry>
        <mesh filename="/home/r2ci/eagerx-dev/eagerx_interbotix/eagerx_interbotix/xseries/assets/meshes/vx300s_meshes/vx300s_3_upper_arm.stl" scale="0.001 0.001 0.001"/>
      </geometry>
    </collision>
  </link>
  <joint name="elbow" type="revolute">
    <origin xyz="0.05955 0.0 0.3" rpy="0.0 0.0 0.0"/>
    <axis xyz="0.0 1.0 0.0"/>
    <parent link="vx300s/upper_arm_link"/>
    <child link="vx300s/upper_forearm_link"/>
    <limit effort="15.0" lower="-1.7627825445142729" upper="1.6057029118347832" velocity="3.141592653589793"/>
    <dynamics friction="0.1"/>
  </joint>
  <transmission name="trans_elbow">
    <type>transmission_interface/SimpleTransmission</type>
    <joint name="elbow">
      <hardwareInterface>hardware_interface/EffortJointInterface</hardwareInterface>
    </joint>
    <actuator name="elbow_motor">
      <mechanicalReduction>1.0</mechanicalReduction>
    </actuator>
  </transmission>
  <link name="vx300s/upper_forearm_link">
    <inertial>
      <origin xyz="0.105723 0.0 0.0" rpy="0.0 0.0 0.0"/>
      <mass value="0.322228"/>
      <inertia ixx="0.0001524" ixy="-1.883e-05" ixz="-8.4064e-06" iyy="0.001342" iyz="1.2564e-06" izz="0.001441"/>
    </inertial>
    <visual>
      <origin xyz="0.0 0.0 0.0" rpy="0.0 0.0 0.0"/>
      <geometry>
        <mesh filename="/home/r2ci/eagerx-dev/eagerx_interbotix/eagerx_interbotix/xseries/assets/meshes/vx300s_meshes/vx300s_4_upper_forearm.stl" scale="0.001 0.001 0.001"/>
      </geometry>
      <material name="interbotix_black"/>
    </visual>
    <collision>
      <origin xyz="0.0 0.0 0.0" rpy="0.0 0.0 0.0"/>
      <geometry>
        <mesh filename="/home/r2ci/eagerx-dev/eagerx_interbotix/eagerx_interbotix/xseries/assets/meshes/vx300s_meshes/vx300s_4_upper_forearm.stl" scale="0.001 0.001 0.001"/>
      </geometry>
    </collision>
  </link>
  <joint name="forearm_roll" type="revolute">
    <origin xyz="0.2 0.0 0.0" rpy="0.0 0.0 0.0"/>
    <axis xyz="1.0 0.0 0.0"/>
    <parent link="vx300s/upper_forearm_link"/>
    <child link="vx300s/lower_forearm_link"/>
    <limit effort="2.0" lower="-3.141582653589793" upper="3.141582653589793" velocity="3.141592653589793"/>
    <dynamics friction="0.1"/>
  </joint>
  <transmission name="trans_forearm_roll">
    <type>transmission_interface/SimpleTransmission</type>
    <joint name="forearm_roll">
      <hardwareInterface>hardware_interface/EffortJointInterface</hardwareInterface>
    </joint>
    <actuator name="forearm_roll_motor">
      <mechanicalReduction>1.0</mechanicalReduction>
    </actuator>
  </transmission>
  <link name="vx300s/lower_forearm_link">
    <inertial>
      <origin xyz="0.0513477 0.00680462 0.0" rpy="3.141592653589793 0.0 0.0"/>
      <mass value="0.414823"/>
      <inertia ixx="0.0001753" ixy="-8.528e-05" ixz="0.0" iyy="0.0005269" iyz="0.0" izz="0.0005911"/>
    </inertial>
    <visual>
      <origin xyz="0.0 0.0 0.0" rpy="3.141592653589793 0.0 0.0"/>
      <geometry>
        <mesh filename="/home/r2ci/eagerx-dev/eagerx_interbotix/eagerx_interbotix/xseries/assets/meshes/vx300s_meshes/vx300s_5_lower_forearm.stl" scale="0.001 0.001 0.001"/>
      </geometry>
      <material name="interbotix_black"/>
    </visual>
    <collision>
      <origin xyz="0.0 0.0 0.0" rpy="3.141592653589793 0.0 0.0"/>
      <geometry>
        <mesh filename="/home/r2ci/eagerx-dev/eagerx_interbotix/eagerx_interbotix/xseries/assets/meshes/vx300s_meshes/vx300s_5_lower_forearm.stl" scale="0.001 0.001 0.001"/>
      </geometry>
    </collision>
  </link>
  <joint name="wrist_angle" type="revolute">
    <origin xyz="0.1 0.0 0.0" rpy="0.0 0.0 0.0"/>
    <axis xyz="0.0 1.0 0.0"/>
    <parent link="vx300s/lower_forearm_link"/>
    <child link="vx300s/wrist_link"/>
    <limit effort="5.0" lower="-1.8675022996339325" upper="2.234021442552742" velocity="3.141592653589793"/>
    <dynamics friction="0.1"/>
  </joint>
  <transmission name="trans_wrist_angle">
    <type>transmission_interface/SimpleTransmission</type>
    <joint name="wrist_angle">
      <hardwareInterface>hardware_interface/EffortJointInterface</hardwareInterface>
    </joint>
    <actuator name="wrist_angle_motor">
      <mechanicalReduction>1.0</mechanicalReduction>
    </actuator>
  </transmission>
  <link name="vx300s/wrist_link">
    <inertial>
      <origin xyz="0.046743 -7.6652e-06 0.010565" rpy="0.0 0.0 1.5707963267948966"/>
      <mass value="0.115395"/>
      <inertia ixx="4.631e-05" ixy="1.95e-08" ixz="2.3e-09" iyy="4.514e-05" iyz="4.2002e-06" izz="5.27e-05"/>
    </inertial>
    <visual>
      <origin xyz="0.0 0.0 0.0" rpy="0.0 0.0 1.5707963267948966"/>
      <geometry>
        <mesh filename="/home/r2ci/eagerx-dev/eagerx_interbotix/eagerx_interbotix/xseries/assets/meshes/vx300s_meshes/vx300s_6_wrist.stl" scale="0.001 0.001 0.001"/>
      </geometry>
      <material name="interbotix_black"/>
    </visual>
    <collision>
      <origin xyz="0.0 0.0 0.0" rpy="0.0 0.0 1.5707963267948966"/>
      <geometry>
        <mesh filename="/home/r2ci/eagerx-dev/eagerx_interbotix/eagerx_interbotix/xseries/assets/meshes/vx300s_meshes/vx300s_6_wrist.stl" scale="0.001 0.001 0.001"/>
      </geometry>
    </collision>
  </link>
  <joint name="wrist_rotate" type="revolute">
    <origin xyz="0.069744 0.0 0.0" rpy="0.0 0.0 0.0"/>
    <axis xyz="1.0 0.0 0.0"/>
    <parent link="vx300s/wrist_link"/>
    <child link="vx300s/gripper_link"/>
    <limit effort="1.0" lower="-3.141582653589793" upper="3.141582653589793" velocity="3.141592653589793"/>
    <dynamics friction="0.1"/>
  </joint>
  <transmission name="trans_wrist_rotate">
    <type>transmission_interface/SimpleTransmission</type>
    <joint name="wrist_rotate">
      <hardwareInterface>hardware_interface/EffortJointInterface</hardwareInterface>
    </joint>
    <actuator name="wrist_rotate_motor">
      <mechanicalReduction>1.0</mechanicalReduction>
    </actuator>
  </transmission>
  <link name="vx300s/gripper_link">
    <inertial>
      <origin xyz="0.023001 0.0 0.011523" rpy="0.0 0.0 1.5707963267948966"/>
      <mass value="0.097666"/>
      <inertia ixx="3.268e-05" ixy="0.0" ixz="0.0" iyy="2.436e-05" iyz="2.785e-07" izz="2.119e-05"/>
    </inertial>
    <visual>
      <origin xyz="-0.02 0.0 0.0" rpy="0.0 0.0 1.5707963267948966"/>
      <geometry>
        <mesh filename="/home/r2ci/eagerx-dev/eagerx_interbotix/eagerx_interbotix/xseries/assets/meshes/vx300s_meshes/vx300s_7_gripper.stl" scale="0.001 0.001 0.001"/>
      </geometry>
      <material name="interbotix_black"/>
    </visual>
    <collision>
      <origin xyz="-0.02 0.0 0.0" rpy="0.0 0.0 1.5707963267948966"/>
      <geometry>
        <mesh filename="/home/r2ci/eagerx-dev/eagerx_interbotix/eagerx_interbotix/xseries/assets/meshes/vx300s_meshes/vx300s_7_gripper.stl" scale="0.001 0.001 0.001"/>
      </geometry>
    </collision>
  </link>
  <joint name="ee_arm" type="fixed">
    <origin xyz="0.042825 0.0 0.0" rpy="0.0 0.0 0.0"/>
    <axis xyz="1.0 0.0 0.0"/>
    <parent link="vx300s/gripper_link"/>
    <child link="vx300s/ee_arm_link"/>
  </joint>
  <link name="vx300s/ee_arm_link">
    <inertial>
      <mass value="0.001"/>
      <inertia ixx="0.0001" ixy="0.0" ixz="0.0" iyy="0.0001" iyz="0.0" izz="0.0001"/>
    </inertial>
  </link>
  <joint name="gripper" type="continuous">
    <origin xyz="0.005675 0.0 0.0" rpy="0.0 0.0 0.0"/>
    <axis xyz="1.0 0.0 0.0"/>
    <parent link="vx300s/ee_arm_link"/>
    <child link="vx300s/gripper_prop_link"/>
    <limit effort="1.0" lower="0" upper="0" velocity="3.141592653589793"/>
    <dynamics friction="0.1"/>
  </joint>
  <transmission name="trans_gripper">
    <type>transmission_interface/SimpleTransmission</type>
    <joint name="gripper">
      <hardwareInterface>hardware_interface/EffortJointInterface</hardwareInterface>
    </joint>
    <actuator name="gripper_motor">
      <mechanicalReduction>1.0</mechanicalReduction>
    </actuator>
  </transmission>
  <link name="vx300s/gripper_prop_link">
    <inertial>
      <origin xyz="0.002378 2.85e-08 0.0" rpy="0.0 0.0 1.5707963267948966"/>
      <mass value="0.008009"/>
      <inertia ixx="2.0386e-06" ixy="0.0" ixz="6.559e-07" iyy="4.2979e-06" iyz="0.0" izz="2.3796e-06"/>
    </inertial>
    <visual>
      <origin xyz="-0.0685 0.0 0.0" rpy="0.0 0.0 1.5707963267948966"/>
      <geometry>
        <mesh filename="/home/r2ci/eagerx-dev/eagerx_interbotix/eagerx_interbotix/xseries/assets/meshes/vx300s_meshes/vx300s_8_gripper_prop.stl" scale="0.001 0.001 0.001"/>
      </geometry>
      <material name="interbotix_black"/>
    </visual>
    <collision>
      <origin xyz="-0.0685 0.0 0.0" rpy="0.0 0.0 1.5707963267948966"/>
      <geometry>
        <mesh filename="/home/r2ci/eagerx-dev/eagerx_interbotix/eagerx_interbotix/xseries/assets/meshes/vx300s_meshes/vx300s_8_gripper_prop.stl" scale="0.001 0.001 0.001"/>
      </geometry>
    </collision>
  </link>
  <joint name="gripper_bar" type="fixed">
    <origin xyz="0.0 0.0 0.0" rpy="0.0 0.0 0.0"/>
    <axis xyz="1.0 0.0 0.0"/>
    <parent link="vx300s/ee_arm_link"/>
    <child link="vx300s/gripper_bar_link"/>
  </joint>
  <link name="vx300s/gripper_bar_link">
    <inertial>
      <origin xyz="0.006794 -4.272e-07 -0.000776" rpy="0.0 0.0 1.5707963267948966"/>
      <mass value="0.150986"/>
      <inertia ixx="7.895e-05" ixy="-1.2e-09" ixz="1.341e-07" iyy="0.0003283" iyz="1.7465e-06" izz="0.0003095"/>
    </inertial>
    <visual>
      <origin xyz="-0.063 0.0 0.0" rpy="0.0 0.0 1.5707963267948966"/>
      <geometry>
        <mesh filename="/home/r2ci/eagerx-dev/eagerx_interbotix/eagerx_interbotix/xseries/assets/meshes/vx300s_meshes/vx300s_9_gripper_bar.stl" scale="0.001 0.001 0.001"/>
      </geometry>
      <material name="interbotix_black"/>
    </visual>
    <collision>
      <origin xyz="-0.063 0.0 0.0" rpy="0.0 0.0 1.5707963267948966"/>
      <geometry>
        <mesh filename="/home/r2ci/eagerx-dev/eagerx_interbotix/eagerx_interbotix/xseries/assets/meshes/vx300s_meshes/vx300s_9_gripper_bar.stl" scale="0.001 0.001 0.001"/>
      </geometry>
    </collision>
  </link>
  <joint name="ee_bar" type="fixed">
    <origin xyz="0.025875 0.0 0.0" rpy="0.0 0.0 0.0"/>
    <axis xyz="1.0 0.0 0.0"/>
    <parent link="vx300s/gripper_bar_link"/>
    <child link="vx300s/fingers_link"/>
  </joint>
  <link name="vx300s/fingers_link">
    <inertial>
      <mass value="0.001"/>
      <inertia ixx="0.0001" ixy="0.0" ixz="0.0" iyy="0.0001" iyz="0.0" izz="0.0001"/>
    </inertial>
  </link>
  <joint name="left_finger" type="prismatic">
    <origin xyz="0.0 0.0 0.0" rpy="0.0 0.0 0.0"/>
    <axis xyz="0.0 1.0 0.0"/>
    <parent link="vx300s/fingers_link"/>
    <child link="vx300s/left_finger_link"/>
    <limit effort="5.0" lower="0.021" upper="0.057" velocity="1.0"/>
    <dynamics friction="0.1"/>
  </joint>
  <transmission name="trans_left_finger">
    <type>transmission_interface/SimpleTransmission</type>
    <joint name="left_finger">
      <hardwareInterface>hardware_interface/EffortJointInterface</hardwareInterface>
    </joint>
    <actuator name="left_finger_motor">
      <mechanicalReduction>1.0</mechanicalReduction>
    </actuator>
  </transmission>
  <link name="vx300s/left_finger_link">
    <inertial>
      <origin xyz="0.017344 -0.0060692 0.0" rpy="3.141592653589793 3.141592653589793 1.5707963267948966"/>
      <mass value="0.034796"/>
      <inertia ixx="2.433e-05" ixy="-2.4004e-06" ixz="0.0" iyy="1.255e-05" iyz="0.0" izz="1.417e-05"/>
    </inertial>
    <visual>
      <origin xyz="-0.0404 -0.0575 0.0" rpy="1.5707963267948966 -3.141592653589793 1.5707963267948966"/>
      <geometry>
        <mesh filename="/home/r2ci/eagerx-dev/eagerx_interbotix/eagerx_interbotix/xseries/assets/meshes/vx300s_meshes/vx300s_10_gripper_finger.stl" scale="0.001 0.001 0.001"/>
      </geometry>
      <material name="interbotix_black"/>
    </visual>
    <collision>
      <origin xyz="-0.0404 -0.0575 0.0" rpy="1.5707963267948966 -3.141592653589793 1.5707963267948966"/>
      <geometry>
        <mesh filename="/home/r2ci/eagerx-dev/eagerx_interbotix/eagerx_interbotix/xseries/assets/meshes/vx300s_meshes/vx300s_10_gripper_finger.stl" scale="0.001 0.001 0.001"/>
      </geometry>
    </collision>
  </link>
  <joint name="right_finger" type="prismatic">
    <origin xyz="0.0 0.0 0.0" rpy="0.0 0.0 0.0"/>
    <axis xyz="0.0 1.0 0.0"/>
    <parent link="vx300s/fingers_link"/>
    <child link="vx300s/right_finger_link"/>
    <limit effort="5.0" lower="-0.057" upper="-0.021" velocity="1.0"/>
    <dynamics friction="0.1"/>
    <mimic joint="left_finger" multiplier="-1.0" offset="0.0"/>
  </joint>
  <transmission name="trans_right_finger">
    <type>transmission_interface/SimpleTransmission</type>
    <joint name="right_finger">
      <hardwareInterface>hardware_interface/EffortJointInterface</hardwareInterface>
    </joint>
    <actuator name="right_finger_motor">
      <mechanicalReduction>1.0</mechanicalReduction>
    </actuator>
  </transmission>
  <link name="vx300s/right_finger_link">
    <inertial>
      <origin xyz="0.017344 0.0060692 0.0" rpy="0.0 3.141592653589793 1.5707963267948966"/>
      <mass value="0.034796"/>
      <inertia ixx="2.433e-05" ixy="2.4001e-06" ixz="0.0" iyy="1.255e-05" iyz="0.0" izz="1.417e-05"/>
    </inertial>
    <visual>
      <origin xyz="-0.0404 0.0575 0.0" rpy="-1.5707963267948966 3.141592653589793 -1.5707963267948966"/>
      <geometry>
        <mesh filename="/home/r2ci/eagerx-dev/eagerx_interbotix/eagerx_interbotix/xseries/assets/meshes/vx300s_meshes/vx300s_10_gripper_finger.stl" scale="0.001 0.001 0.001"/>
      </geometry>
      <material name="interbotix_black"/>
    </visual>
    <collision>
      <origin xyz="-0.0404 0.0575 0.0" rpy="-1.5707963267948966 3.141592653589793 -1.5707963267948966"/>
      <geometry>
        <mesh filename="/home/r2ci/eagerx-dev/eagerx_interbotix/eagerx_interbotix/xseries/assets/meshes/vx300s_meshes/vx300s_10_gripper_finger.stl" scale="0.001 0.001 0.001"/>
      </geometry>
    </collision>
  </link>
  <joint name="ee_gripper" type="fixed">
    <origin xyz="0.0385 0.0 0.0" rpy="0.0 0.0 0.0"/>
    <axis xyz="1.0 0.0 0.0"/>
    <parent link="vx300s/fingers_link"/>
    <child link="vx300s/ee_gripper_link"/>
  </joint>
  <link name="vx300s/ee_gripper_link">
    <inertial>
      <mass value="0.001"/>
      <inertia ixx="0.0001" ixy="0.0" ixz="0.0" iyy="0.0001" iyz="0.0" izz="0.0001"/>
    </inertial>
  </link>
</robot>