<mujoco model="disk_pendulum">
    <compiler inertiafromgeom="auto" angle="radian" coordinate="local" eulerseq="xyz" autolimits="true"/>
    <option gravity="0 0 -9.81" timestep="0.01" iterations="10"/>
    <custom>
        <numeric data="10" name="constraint_ang_damping"/> <!-- positional & spring -->
        <numeric data="1" name="spring_inertia_scale"/>  <!-- positional & spring -->
        <numeric data="0" name="ang_damping"/>  <!-- positional & spring -->
        <numeric data="0" name="spring_mass_scale"/>  <!-- positional & spring -->
        <numeric data="0.5" name="joint_scale_pos"/> <!-- positional -->
        <numeric data="0.1" name="joint_scale_ang"/> <!-- positional -->
        <numeric data="3000" name="constraint_stiffness"/>  <!-- spring -->
        <numeric data="10000" name="constraint_limit_stiffness"/>  <!-- spring -->
        <numeric data="50" name="constraint_vel_damping"/>  <!-- spring -->
        <numeric data="10" name="solver_maxls"/>  <!-- generalized -->
    </custom>

    <asset>
        <texture builtin="flat" height="1278" mark="cross" markrgb="1 1 1" name="texgeom" random="0.01" rgb1="0.8 0.6 0.4" rgb2="0.8 0.6 0.4" type="cube" width="127"/>
        <material name="geom" texture="texgeom" texuniform="true"/>
    </asset>

    <default>
        <geom contype="0" friction="1 0.1 0.1" material="geom"/>
    </default>

    <worldbody>
        <light cutoff="100" diffuse="1 1 1" dir="-0 0 -1.3" directional="true" exponent="1" pos="0 0 1.3" specular=".1 .1 .1"/>
        <geom name="table" type="plane" pos="0 0.0 -0.1" size="1 1 0.1" contype="8" conaffinity="11" condim="3"/>
        <body name="disk" pos="0.0 0.0 0.0" euler="1.5708 0.0 0.0">
            <joint name="hinge_joint" type="hinge" axis="0 0 1" range="-180 180" armature="0.00022993" damping="0.0001" limited="false" frictionloss="123"/>
            <geom name="disk_geom" type="cylinder" size="0.06 0.001" contype="0" conaffinity="0" condim="3" mass="0.0"/>
            <geom name="mass_geom" type="cylinder" size="0.02 0.005" contype="0" conaffinity="0"  condim="3" rgba="0.04 0.04 0.04 1"
                  pos="0.0 0.04 0." mass="0.05085817"/>
        </body>
    </worldbody>

    <actuator>
        <motor joint="hinge_joint" ctrllimited="false" ctrlrange="-3.0 3.0"  gear="0.01"/>
    </actuator>
</mujoco>